testdata/in/throw_empty_inside_catch_nested_fn.nen:3:3: invalid re-throw: not inside a catch block
